<?xml version="1.0" ?>
<robot name="agv_robot">

  <link name="base_link" /> 

  <link name="link_chassis">
    <!-- pose and inertial -->
    <inertial>
      <mass value="50" />
      <origin xyz="0 0 0" rpy="0 0 0" />
      <inertia
        ixx="4.69"
        ixy="0"
        ixz="0"
        iyy="5.77"
        iyz="0"
        izz="7.08" />
    </inertial>
    <visual>
      <origin xyz="-0.35 0 0" rpy="0 0 -1.5708" />
      <geometry>
        <mesh filename="package://meshes/AMR_CAD_v1.stl" scale="0.001 0.001 0.001"/>
      </geometry>
      <material name="">
          <color rgba="0.79216 0.81961 0.93333 1" />
      </material>
    </visual>
  </link>

  <joint name="base_link_joint" type="fixed">
    <parent link="base_link"/>
    <child link="link_chassis" />
    <origin xyz="0 0 0.05" rpy="0 0 0"/>
  </joint>

  <!-- left wheel -->
  <link name="link_left_wheel">
    <inertial>
      <mass value="3.0" />
      <origin xyz="0 0 0" rpy="0 0 0" />
      <inertia
        ixx="0.00856502765719703"
        ixy="1.5074118157338E-19"
        ixz="-4.78150098725052E-19"
        iyy="0.013670640432096"
        iyz="-2.68136447099727E-19"
        izz="0.00856502765719703" />
    </inertial>
    <visual>
      <origin xyz="0 0 0" rpy="0 1.5708 1.5708" />
      <geometry>
        <cylinder length="0.03" radius="0.05" />
      </geometry>
      <material name="">
        <color rgba="0.79216 0.81961 0.93333 1" />
      </material>
    </visual>
    <collision>
      <origin xyz="0 0 0" rpy="0 1.5708 1.5708" />
      <geometry>
        <cylinder length="0.03" radius="0.05" />
      </geometry>
    </collision>
  </link>

  <joint name="joint_left_wheel" type="continuous">
    <parent link="link_chassis" />
    <child link="link_left_wheel" />
    <origin xyz="0 -0.23 0" rpy="0 0 0" />
    <axis xyz="0 1 0" />
    <dynamics damping="0.5"/>
    <limit effort="10" velocity="20"/>
  </joint>

  <!-- right wheel -->
  <link name="link_right_wheel">
    <inertial>
      <mass value="3.0" />
      <origin xyz="0 0 0" rpy="0 0 0" />
      <inertia
        ixx="0.00856502765719703"
        ixy="1.5074118157338E-19"
        ixz="-4.78150098725052E-19"
        iyy="0.013670640432096"
        iyz="-2.68136447099727E-19"
        izz="0.00856502765719703" />
    </inertial>
    <visual>
      <origin xyz="0 0 0" rpy="0 1.5708 1.5708" />
      <geometry>
        <cylinder length="0.03" radius="0.05" />
      </geometry>
      <material name="gray" />
    </visual>
    <collision>
      <origin xyz="0 0 0" rpy="0 1.5708 1.5708" />
      <geometry>
        <cylinder length="0.03" radius="0.05" />
      </geometry>
    </collision>
  </link>

  <joint name="joint_right_wheel" type="continuous">
    <parent link="link_chassis" />
    <child link="link_right_wheel" />
    <origin xyz="0 0.23 0" rpy="0 0 0" />
    <axis xyz="0 1 0" />
    <dynamics damping="0.5"/>
    <limit effort="10" velocity="20"/>
  </joint>

  <!-- Front left caster wheel -->
  <link name="front_left_caster">
    <inertial>
      <mass value="1.0" />
      <origin xyz="0 0 0" rpy="0 0 0" />
      <inertia ixx="0.0005" ixy="0.0" ixz="0.0" iyy="0.0005" iyz="0.0" izz="0.0005" />
    </inertial>
    <visual>
      <origin xyz="0 0 0" rpy="0 1.5708 1.5708" />
      <geometry>
        <cylinder length="0.03" radius="0.04" />
      </geometry>
      <material name="black" />
    </visual>
    <collision>
      <origin xyz="0 0 0" rpy="0 1.5708 1.5708" />
      <geometry>
        <cylinder length="0.03" radius="0.04" />
      </geometry>
    </collision>
  </link>

  <joint name="front_left_caster_joint" type="continuous">
    <parent link="link_chassis" />
    <child link="front_left_caster" />
    <origin xyz="-0.3 0.23 -0.01" rpy="0 0 0" />
    <axis xyz="0 1 0" />
    <dynamics damping="0.5"/>
    <limit effort="10" velocity="20"/>
  </joint>

  <!-- Front right caster wheel -->
  <link name="front_right_caster">
    <inertial>
      <mass value="1.0" />
      <origin xyz="0 0 0" rpy="0 0 0" />
      <inertia ixx="0.0005" ixy="0.0" ixz="0.0" iyy="0.0005" iyz="0.0" izz="0.0005" />
    </inertial>
    <visual>
      <origin xyz="0 0 0" rpy="0 1.5708 1.5708" />
      <geometry>
        <cylinder length="0.03" radius="0.04" />
      </geometry>
      <material name="black" />
    </visual>
    <collision>
      <origin xyz="0 0 0" rpy="0 1.5708 1.5708" />
      <geometry>
        <cylinder length="0.03" radius="0.04" />
      </geometry>
    </collision>
  </link>

  <joint name="front_right_caster_joint" type="continuous">
    <parent link="link_chassis" />
    <child link="front_right_caster" />
    <origin xyz="-0.3 -0.23 -0.01" rpy="0 0 0" />
    <axis xyz="0 1 0" />
    <dynamics damping="0.5"/>
    <limit effort="10" velocity="20"/>
  </joint>

  <!-- Rear left caster wheel -->
  <link name="rear_left_caster">
    <inertial>
      <mass value="1.0" />
      <origin xyz="0 0 0" rpy="0 1.5708 1.5708" />
      <inertia ixx="0.0005" ixy="0.0" ixz="0.0" iyy="0.0005" iyz="0.0" izz="0.0005" />
    </inertial>
    <visual>
      <origin xyz="0 0 0" rpy="0 1.5708 1.5708" />
      <geometry>
        <cylinder length="0.03" radius="0.04" />
      </geometry>
      <material name="black" />
    </visual>
    <collision>
      <origin xyz="0 0 0" rpy="0 1.5708 1.5708" />
      <geometry>
        <cylinder length="0.03" radius="0.04" />
      </geometry>
    </collision>
  </link>

  <joint name="rear_left_caster_joint" type="continuous">
    <parent link="link_chassis" />
    <child link="rear_left_caster" />
    <origin xyz="0.3 0.23 -0.01" rpy="0 0 0" />
    <axis xyz="0 1 0" />
    <dynamics damping="0.5"/>
    <limit effort="10" velocity="20"/>
  </joint>

  <!-- Rear right caster wheel -->
  <link name="rear_right_caster">
    <inertial>
      <mass value="1.0" />
      <origin xyz="0 0 0" rpy="0 1.5708 1.5708" />
      <inertia ixx="0.0005" ixy="0.0" ixz="0.0" iyy="0.0005" iyz="0.0" izz="0.0005" />
    </inertial>
    <visual>
      <origin xyz="0 0 0" rpy="0 1.5708 1.5708" />
      <geometry>
        <cylinder length="0.03" radius="0.04" />
      </geometry>
      <material name="black" />
    </visual>
    <collision>
      <origin xyz="0 0 0" rpy="0 0 0" />
      <geometry>
        <cylinder length="0.03" radius="0.04" />
      </geometry>
    </collision>
  </link>

  <joint name="rear_right_caster_joint" type="continuous">
    <parent link="link_chassis" />
    <child link="rear_right_caster" />
    <origin xyz="0.3 -0.23 -0.01" rpy="0 0 0" />
    <axis xyz="0 1 0" />
    <dynamics damping="0.5"/>
    <limit effort="10" velocity="20"/>
  </joint>

  <!-- add Sick_tim_link -->
  <!-- <link name="laser">
    <inertial>
      <mass value="0.1" />
      <origin xyz="0 0 0" rpy="0 0 0" />
      <inertia ixx="0.0001" ixy="0.0" ixz="0.0" iyy="0.0001" iyz="0.0" izz="0.0001" />
    </inertial>
    <visual>
      <origin xyz="0.0 0.0 0.0" rpy="0 0 0" />
      <geometry>
        <cylinder length="0.05" radius="0.03" />
        <mesh filename="package://sick_tim/meshes/sick_tim551.stl"/>
      </geometry>
      <material name="orange" />
    </visual>
    <collision>
      <origin xyz="0.0 0.0 0.0" rpy="0 0 0" />
      <geometry>
        <cylinder length="0.05" radius="0.03" />
      </geometry>
    </collision>
  </link> -->

  <!-- <joint name="base_link_to_lidar_joint" type="fixed">
    <parent link="link_chassis" />
    <child link="laser" />
    <origin xyz="0.35 0.0 0.08" />
  </joint> -->

  <material name="gray">
      <color rgba="0.5 0.5 0.5 1.0" />
  </material>
  <material name="white">
      <color rgba="0.95 0.95 0.95 1.0" />
  </material>
  <material name="red">
      <color rgba="0.95 0.0 0.0 1.0" />
  </material>
  <material name="orange">
      <color rgba="1.0 0.5 0.0 1.0" />
  </material>
  <material name="yellow">
      <color rgba="1.0 1.0 0.0 1.0" />
  </material>
  <material name="green">
      <color rgba="0.0 1.0 0.0 1.0" />
  </material>
  <material name="blue">
      <color rgba="0.0 0.0 1.0 1.0" />
  </material>
  <material name="indigo">
      <color rgba="0.3 0.3 0.6 1.0" />
  </material>
  <material name="violet">
      <color rgba="0.6 0.0 1.0 1.0" />
  </material>
  <material name="black">
      <color rgba="0.0 0.0 0.0 1.0" />
  </material>
  
</robot>
